sample/_MessageBook3.txt
A,1001,S,10,100
G,1002,S,12,110
A,1003,H,15,120
A,1004,B,-5,130
X,1005,B,10,-20
A,SALT,S,10,140
M,1006,S,HI,140
A,1007,B,25,BOY
A,SALT,S,40,BOY
M,B002,S,-2,150
A,2001,S,10,100,R
A,2002,S,10,100,R,S,T
Q,2003,S,10,-50,F1
A,5001,S,50,500
A,5001,B,60,600
M,5002,S,80,800
A,8001,S,10,100
X,8002,S,10,100
X,8001,B,10,100
X,8001,S,20,100
X,8001,S,10,200
