sample/_MessageBook5.txt
A,101,B,15,379
A,102,S,15,357
A,103,B,17,367
A,104,B,16,368
A,105,S,15,364
A,106,S,15,379
A,107,B,18,391
A,108,B,16,361
A,109,S,15,377
A,110,B,19,389
A,111,S,16,389
A,112,S,19,369
A,113,B,19,374
M,107,B,18,363
A,115,S,20,364
X,107,B,18,363
A,117,B,16,398
X,106,S,15,379
A,119,S,17,389
A,120,B,20,354
M,113,B,21,374
A,122,S,17,350
A,123,S,19,365
M,110,B,18,389
A,125,S,15,399
A,126,B,19,372
A,127,S,15,379
X,111,S,16,389
A,129,S,20,368
X,126,B,19,372
A,131,B,17,384
A,132,B,16,357
A,133,B,18,385
A,134,B,16,364
A,135,S,18,375
M,122,S,17,363
X,131,B,17,384
X,125,S,15,399
M,117,B,18,398
M,120,B,20,362
